<?xml version="1.0" encoding="utf-8"?>
<robot xmlns:xacro="http://www.ros.org/wiki/xacro" name="hand">
  <xacro:macro name="hand" params="connected_to:='' ns:='' rpy:='0 0 0' xyz:='0 0 0' ">
    <xacro:unless value="${connected_to == ''}">
      <joint name="${ns}_hand_joint" type="fixed">
        <parent link="${connected_to}"/>
        <child link="${ns}_hand"/>
        <origin xyz="${xyz}" rpy="${rpy}"/>
      </joint>
    </xacro:unless>

    <link name="${ns}_hand">
      <visual>
        <geometry>
          <mesh filename="package://panda_sim_description/meshes/franka_panda/visual/hand.dae"/>
        </geometry>
      </visual>
      <collision>
        <geometry>
          <mesh filename="package://panda_sim_description/meshes/franka_panda/collision/hand.stl"/>
        </geometry>
      </collision>
      <inertial>
        <mass value="0.73" />
        <origin xyz="0 0.0015244 0.0275912" rpy="0 0 0" />
        <inertia ixx="0.00278560230025" ixy="0.0" ixz="0.0" iyy="0.000400033405336" iyz="0.0" izz="0.00256378041832" />
      </inertial>

    </link>

  <gazebo reference="${ns}_hand">
      <mu1>0.61</mu1>
      <mu2>0.61</mu2>
    </gazebo>

    <link name="${ns}_leftfinger">
      <visual>
        <geometry>
          <mesh filename="package://panda_sim_description/meshes/franka_panda/visual/finger.dae"/>
        </geometry>
      </visual>
      <collision>
        <geometry>
          <mesh filename="package://panda_sim_description/meshes/franka_panda/collision/finger.stl"/>
        </geometry>
      </collision>
      <inertial>
        <mass value="0.1" />
        <origin xyz="0 0.0145644 0.0227941" rpy="0 0 0" />
        <inertia ixx="3.01220925051e-05" ixy="0.0" ixz="0.0" iyy="2.95873808038e-05" iyz="0.0" izz="6.95125211657e-06" />
      </inertial>

    </link>

    <gazebo reference="${ns}_leftfinger">
      <mu1>0.61</mu1>
      <mu2>0.61</mu2>
    </gazebo>

    <link name="${ns}_rightfinger">
      <visual>
        <origin xyz="0 0 0" rpy="0 0 ${pi}"/>
        <geometry>
          <mesh filename="package://panda_sim_description/meshes/franka_panda/visual/finger.dae"/>
        </geometry>
      </visual>
      <collision>
        <origin xyz="0 0 0" rpy="0 0 ${pi}"/>
        <geometry>
          <mesh filename="package://panda_sim_description/meshes/franka_panda/collision/finger.stl"/>
        </geometry>
      </collision>
       <inertial>
        <mass value="0.1" />
        <origin xyz="0 0.0145644 0.0227941" rpy="0 0 ${pi}" />
        <inertia ixx="3.01220925051e-05" ixy="0.0" ixz="0.0" iyy="2.95873808038e-05" iyz="0.0" izz="6.95125211657e-06" />
      </inertial>

    </link>

    <gazebo reference="${ns}_rightfinger">
      <mu1>0.61</mu1>
      <mu2>0.61</mu2>
    </gazebo>

    <joint name="${ns}_finger_joint1" type="prismatic">
      <parent link="${ns}_hand"/>
      <child link="${ns}_leftfinger"/>
      <origin xyz="0 0 0.0584" rpy="0 0 0"/>
      <axis xyz="0 1 0"/>
      <limit effort="20" lower="-0.001" upper="0.04" velocity="0.3"/>
      <dynamics damping="0.0" friction="1.0"/>
    </joint>

    <transmission name="${ns}_finger_joint1_trans">
      <type>transmission_interface/SimpleTransmission</type>
      <joint name="${ns}_finger_joint1">
        <hardwareInterface>hardware_interface/PositionJointInterface</hardwareInterface>
      </joint>
      <actuator name="${ns}_finger_joint1_motor">
        <mechanicalReduction>1</mechanicalReduction>
      </actuator>
    </transmission>

    <joint name="${ns}_finger_joint2" type="prismatic">
      <parent link="${ns}_hand"/>
      <child link="${ns}_rightfinger"/>
      <origin xyz="0 0 0.0584" rpy="0 0 0"/>
      <axis xyz="0 -1 0"/>
      <limit effort="20" lower="-0.001" upper="0.04" velocity="0.3"/>
      <dynamics damping="0.0" friction="1.0"/>
    </joint>

    <transmission name="${ns}_finger_joint2_trans">
      <type>transmission_interface/SimpleTransmission</type>
      <joint name="${ns}_finger_joint2">
        <hardwareInterface>hardware_interface/PositionJointInterface</hardwareInterface>
      </joint>
      <actuator name="${ns}_finger_joint2_motor">
        <mechanicalReduction>1</mechanicalReduction>
      </actuator>
    </transmission>

  </xacro:macro>
</robot>

